This solution demonstrates robust error handling using a try-catch block to handle any exceptions thrown during the asynchronous operation.
```javascript
// bugSolution.js
import { unstable_getServerSession } from 'next-auth' 
import { authOptions } from '@/pages/api/auth/[...nextauth]' 

export async function getServerSideProps(context) {
  try {
    const session = await unstable_getServerSession(context, authOptions)
    // ... rest of your code

    return {
      props: {
        session
      }
    }
  } catch (error) {
    console.error('Error during getServerSideProps:', error)
    return {
      redirect: {
        destination: '/error', // Redirect to an error page
        permanent: false
      }
    }
  }
}
```